Workbook
Name EmployeeNames: 'Employee Records'!$A$2:$A$2047
Name EmployeePickList5: 'Employee Dropdown Lists'!$A$2:$A$201
Name EmployeePickList6: 'Employee Dropdown Lists'!$B$2:$B$201
Name EmployeePickList7: 'Employee Dropdown Lists'!$C$2:$C$201
Name EmployeePickList8: 'Employee Dropdown Lists'!$D$2:$D$201
Name EmployeePickList9: 'Employee Dropdown Lists'!$E$2:$E$201
Name EmployeePickList10: 'Employee Dropdown Lists'!$F$2:$F$201
Name EmployeePickList11: 'Employee Dropdown Lists'!$G$2:$G$201
Name EmployeePickList12: 'Employee Dropdown Lists'!$H$2:$H$201
Name EmployeePickList13: 'Employee Dropdown Lists'!$I$2:$I$201
Name EmployeePickList14: 'Employee Dropdown Lists'!$J$2:$J$201
Name EmployeePickList15: 'Employee Dropdown Lists'!$K$2:$K$201
Name EmployeePickList16: 'Employee Dropdown Lists'!$L$2:$L$201
Name EmployeePickList17: 'Employee Dropdown Lists'!$M$2:$M$201
Name EmployeePickList18: 'Employee Dropdown Lists'!$N$2:$N$201
Name EmployeePickList19: 'Employee Dropdown Lists'!$O$2:$O$201
Name EmployeePickList20: 'Employee Dropdown Lists'!$P$2:$P$201
Name EmployeePickList21: 'Employee Dropdown Lists'!$Q$2:$Q$201
Name EmployeePickList22: 'Employee Dropdown Lists'!$R$2:$R$201
Name EmployeePickList23: 'Employee Dropdown Lists'!$S$2:$S$201
Name EmployeePickList24: 'Employee Dropdown Lists'!$T$2:$T$201
Name EmployeePickList25: 'Employee Dropdown Lists'!$U$2:$U$201
Name EmployeePickList26: 'Employee Dropdown Lists'!$V$2:$V$201
Name EmployeePickList27: 'Employee Dropdown Lists'!$W$2:$W$201
Name EmployeePickList28: 'Employee Dropdown Lists'!$X$2:$X$201
Name EmployeePickList29: 'Employee Dropdown Lists'!$Y$2:$Y$201
Name EmployeePickList30: 'Employee Dropdown Lists'!$Z$2:$Z$201
Name EmployeePickList31: 'Employee Dropdown Lists'!$AA$2:$AA$201
Name EmployeePickList32: 'Employee Dropdown Lists'!$AB$2:$AB$201
Name EmployeePickList33: 'Employee Dropdown Lists'!$AC$2:$AC$201
Name EmployeePickList34: 'Employee Dropdown Lists'!$AD$2:$AD$201
Name EmployeePickList35: 'Employee Dropdown Lists'!$AE$2:$AE$201
Name EmployeePickList36: 'Employee Dropdown Lists'!$AF$2:$AF$201
Name EmployeePickList37: 'Employee Dropdown Lists'!$AG$2:$AG$201
Name EmployeePickList38: 'Employee Dropdown Lists'!$AH$2:$AH$201
Name EmployeePickList39: 'Employee Dropdown Lists'!$AI$2:$AI$201
Name EmployeePickList40: 'Employee Dropdown Lists'!$AJ$2:$AJ$201
Name EmployeePickList41: 'Employee Dropdown Lists'!$AK$2:$AK$201
Name EmployeePickList42: 'Employee Dropdown Lists'!$AL$2:$AL$201
Name EmployeePickList43: 'Employee Dropdown Lists'!$AM$2:$AM$201
Name EmployeePickList44: 'Employee Dropdown Lists'!$AN$2:$AN$201
Name EmployeePickList45: 'Employee Dropdown Lists'!$AO$2:$AO$201
Name EmployeePickList46: 'Employee Dropdown Lists'!$AP$2:$AP$201
Name EmployeePickList47: 'Employee Dropdown Lists'!$AQ$2:$AQ$201
Name EmployeePickList48: 'Employee Dropdown Lists'!$AR$2:$AR$201
Name EmployeePickList49: 'Employee Dropdown Lists'!$AS$2:$AS$201
Name EmployeePickList50: 'Employee Dropdown Lists'!$AT$2:$AT$201
Name EmployeePickList51: 'Employee Dropdown Lists'!$AU$2:$AU$201
Name EmployeePickList52: 'Employee Dropdown Lists'!$AV$2:$AV$201
Name EmployeePickList53: 'Employee Dropdown Lists'!$AW$2:$AW$201
Name EmployeePickList54: 'Employee Dropdown Lists'!$AX$2:$AX$201
Name EmployeePickList55: 'Employee Dropdown Lists'!$AY$2:$AY$201
Name EmployeePickList56: 'Employee Dropdown Lists'!$AZ$2:$AZ$201
Name EmployeePickList57: 'Employee Dropdown Lists'!$BA$2:$BA$201
Name EmployeePickList58: 'Employee Dropdown Lists'!$BB$2:$BB$201
Name EmployeePickList59: 'Employee Dropdown Lists'!$BC$2:$BC$201
Name EmployeePickList60: 'Employee Dropdown Lists'!$BD$2:$BD$201
Name EmployeePickList61: 'Employee Dropdown Lists'!$BE$2:$BE$201
Name EmployeePickList62: 'Employee Dropdown Lists'!$BF$2:$BF$201
Name EmployeePickList63: 'Employee Dropdown Lists'!$BG$2:$BG$201

Sheet Loan Due Import
A1: Entity | B1: GSIS | C1: Use one entity for the whole file.
A4: Due Month | B4: Employee Search | C4: Employee ID | D4: Employee Name | E4: Loan/Account No. | F4: Loan Type | G4: Monthly Amortization | H4: Amount Due | I4: Outstanding Balance | J4: Principal Due | K4: Interest Due | L4: Penalty Due | M4: Remarks
A5: 2026-05-01 | B5: ACOSTA | C5: =IFERROR(VLOOKUP(D5,'Employee Records'!$A$2:$B$2047,2,FALSE),"") -> 002129 | D5: ACOSTA, JESSIE JAMES CALUYA | E5: TEST-002129-0001 | F5: Salary Loan | G5: 1250 | H5: 1275 | I5: 25000 | J5: 1025 | K5: 200 | L5: 50 | M5: Sample IHOMP test row
A6: 2026-05-01 | B6: ACOSTA | C6: =IFERROR(VLOOKUP(D6,'Employee Records'!$A$2:$B$2047,2,FALSE),"") -> 001808 | D6: ACOSTA, JONATHAN CALUYA | E6: TEST-001808-0002 | F6: MPL | G6: 1625.25 | H6: 1592.75 | I6: 29250 | J6: 1332.71 | K6: 260.04 | L6: 0 | M6: Sample IHOMP test row
A7: 2026-05-01 | B7: AGBAYANI | C7: =IFERROR(VLOOKUP(D7,'Employee Records'!$A$2:$B$2047,2,FALSE),"") -> 002515 | D7: AGBAYANI, MARK LAURENCE DOROYAN | E7: TEST-002515-0003 | F7: Emergency Loan | G7: 2000.5 | H7: 1960.49 | I7: 33500 | J7: 1640.41 | K7: 320.08 | L7: 0 | M7: Sample IHOMP test row
A8: 2026-05-01 | B8: AGTANG | C8: =IFERROR(VLOOKUP(D8,'Employee Records'!$A$2:$B$2047,2,FALSE),"") -> 002745 | D8: AGTANG, RHONA MHEA JOY ASUNCION | E8: TEST-002745-0004 | F8: Livelihood Loan | G8: 2375.75 | H8: 2328.24 | I8: 37750 | J8: 1948.12 | K8: 380.12 | L8: 0 | M8: Sample IHOMP test row
A9: 2026-05-01 | B9: AGULAY | C9: =IFERROR(VLOOKUP(D9,'Employee Records'!$A$2:$B$2047,2,FALSE),"") -> 000539 | D9: AGULAY, DENNIS MANGLAL-LAN | E9: TEST-000539-0005 | F9: Calamity Loan | G9: 2751 | H9: 2745.98 | I9: 42000 | J9: 2255.82 | K9: 440.16 | L9: 50 | M9: Sample IHOMP test row
A10: 2026-05-01 | B10: ANDRES | C10: =IFERROR(VLOOKUP(D10,'Employee Records'!$A$2:$B$2047,2,FALSE),"") -> 002966 | D10: ANDRES, STEPHEN JOHN DIVINA | E10: TEST-002966-0006 | F10: Policy Loan | G10: 3126.25 | H10: 3063.73 | I10: 46250 | J10: 2563.53 | K10: 500.2 | L10: 0 | M10: Sample IHOMP test row
A11: 2026-05-01 | B11: CALACAL | C11: =IFERROR(VLOOKUP(D11,'Employee Records'!$A$2:$B$2047,2,FALSE),"") -> 002870 | D11: CALACAL, CARLA NIÑA SADORRA | E11: TEST-002870-0007 | F11: Salary Loan | G11: 3501.5 | H11: 3431.47 | I11: 50500 | J11: 2871.23 | K11: 560.24 | L11: 0 | M11: Sample IHOMP test row
A12: 2026-05-01 | B12: DANCEL | C12: =IFERROR(VLOOKUP(D12,'Employee Records'!$A$2:$B$2047,2,FALSE),"") -> 001165 | D12: DANCEL, CHRISTIAN JAMES BUENO | E12: TEST-001165-0008 | F12: MPL | G12: 3876.75 | H12: 3799.22 | I12: 54750 | J12: 3178.94 | K12: 620.28 | L12: 0 | M12: Sample IHOMP test row
A13: 2026-05-01 | B13: DARIA | C13: =IFERROR(VLOOKUP(D13,'Employee Records'!$A$2:$B$2047,2,FALSE),"") -> 001527 | D13: DARIA, ALDRIN DUMLAO | E13: TEST-001527-0009 | F13: Emergency Loan | G13: 4252 | H13: 4216.96 | I13: 59000 | J13: 3486.64 | K13: 680.32 | L13: 50 | M13: Sample IHOMP test row
A14: 2026-05-01 | B14: DUQUE | C14: =IFERROR(VLOOKUP(D14,'Employee Records'!$A$2:$B$2047,2,FALSE),"") -> 002751 | D14: DUQUE, DAYZELLE MOLINES | E14: TEST-002751-0010 | F14: Livelihood Loan | G14: 4627.25 | H14: 4534.71 | I14: 63250 | J14: 3794.35 | K14: 740.36 | L14: 0 | M14: Sample IHOMP test row
A15: 2026-05-01 | B15: EDNILAO | C15: =IFERROR(VLOOKUP(D15,'Employee Records'!$A$2:$B$2047,2,FALSE),"") -> 002170 | D15: EDNILAO, CHRISTIAN PAUL FUERTES | E15: TEST-002170-0011 | F15: Calamity Loan | G15: 5002.5 | H15: 4902.45 | I15: 67500 | J15: 4102.05 | K15: 800.4 | L15: 0 | M15: Sample IHOMP test row
A16: 2026-05-01 | B16: FORMOSO | C16: =IFERROR(VLOOKUP(D16,'Employee Records'!$A$2:$B$2047,2,FALSE),"") -> 001030 | D16: FORMOSO, RAY VINCENT FLORES | E16: TEST-001030-0012 | F16: Policy Loan | G16: 5377.75 | H16: 5270.2 | I16: 71750 | J16: 4409.76 | K16: 860.44 | L16: 0 | M16: Sample IHOMP test row
C17: =IFERROR(VLOOKUP(D17,'Employee Records'!$A$2:$B$2047,2,FALSE),"")
C18: =IFERROR(VLOOKUP(D18,'Employee Records'!$A$2:$B$2047,2,FALSE),"")
C19: =IFERROR(VLOOKUP(D19,'Employee Records'!$A$2:$B$2047,2,FALSE),"")
C20: =IFERROR(VLOOKUP(D20,'Employee Records'!$A$2:$B$2047,2,FALSE),"")
C21: =IFERROR(VLOOKUP(D21,'Employee Records'!$A$2:$B$2047,2,FALSE),"")
C22: =IFERROR(VLOOKUP(D22,'Employee Records'!$A$2:$B$2047,2,FALSE),"")
C23: =IFERROR(VLOOKUP(D23,'Employee Records'!$A$2:$B$2047,2,FALSE),"")
C24: =IFERROR(VLOOKUP(D24,'Employee Records'!$A$2:$B$2047,2,FALSE),"")
C25: =IFERROR(VLOOKUP(D25,'Employee Records'!$A$2:$B$2047,2,FALSE),"")
C26: =IFERROR(VLOOKUP(D26,'Employee Records'!$A$2:$B$2047,2,FALSE),"")
C27: =IFERROR(VLOOKUP(D27,'Employee Records'!$A$2:$B$2047,2,FALSE),"")
C28: =IFERROR(VLOOKUP(D28,'Employee Records'!$A$2:$B$2047,2,FALSE),"")
... C504: =IFERROR(VLOOKUP(D504,'Employee Records'!$A$2:$B$2047,2,FALSE),"")

Sheet Employee Records
A1: Employee Name | B1: Employee ID | C1: Lastname | D1: Firstname | E1: Middlename
A2: ABAD, FLORIDA RAMOS | B2: 000001 | C2: ABAD | D2: FLORIDA | E2: RAMOS
A3: ABAINZA, SHEENA GRACE BUMAGAT | B3: 001533 | C3: ABAINZA | D3: SHEENA GRACE | E3: BUMAGAT
A4: ABANSI, JELYNNE PISTOLA | B4: 002033 | C4: ABANSI | D4: JELYNNE | E4: PISTOLA
A5: ABARA, REGINA JASMINE RAMOS | B5: 000983 | C5: ABARA | D5: REGINA JASMINE | E5: RAMOS
A6: ABELLA, ADRIENNE RICA BUTAC | B6: 002738 | C6: ABELLA | D6: ADRIENNE RICA | E6: BUTAC
A7: ABELLA, LOVELY JOY BALGUNA | B7: 001648 | C7: ABELLA | D7: LOVELY JOY | E7: BALGUNA
A8: ABELLON, EVIE MAE ACOBA | B8: 001359 | C8: ABELLON | D8: EVIE MAE | E8: ACOBA
A9: ABELLON, GREGG JOHANESS SOLSOLOY | B9: 001103 | C9: ABELLON | D9: GREGG JOHANESS | E9: SOLSOLOY
A10: ABELLON, JAYSON MC ANGELO GALACGAC | B10: 000589 | C10: ABELLON | D10: JAYSON MC ANGELO | E10: GALACGAC
A11: ABELLON, LEO ANGELO GAPUZAN | B11: 002916 | C11: ABELLON | D11: LEO ANGELO | E11: GAPUZAN
A12: ABENES, JESS EMMANUEL VALDEZ | B12: 002613 | C12: ABENES | D12: JESS EMMANUEL | E12: VALDEZ
... A31: ACIERTO, CARLO BANES | B31: 000007 | C31: ACIERTO | D31: CARLO | E31: BANES
A32: ACIO, JENNA MEI AGULLANA | B32: 100001 | C32: ACIO | D32: JENNA MEI | E32: AGULLANA
A33: ACOB, CLARK - ANTHONY BACLIG | B33: 002416 | C33: ACOB | D33: CLARK - ANTHONY | E33: BACLIG
A34: ACOBA, MANUEL CHRISTIENSEN JUSTINE CASTRO | B34: 002929 | C34: ACOBA | D34: MANUEL CHRISTIENSEN JUSTINE | E34: CASTRO
A35: ACOSTA, ANNE GELLE BRIDGITTE GABUTEN | B35: 002233 | C35: ACOSTA | D35: ANNE GELLE BRIDGITTE | E35: GABUTEN
A36: ACOSTA, GENEVE ANDRES | B36: 001865 | C36: ACOSTA | D36: GENEVE | E36: ANDRES
A37: ACOSTA, JAYSON DOMINGO | B37: 002232 | C37: ACOSTA | D37: JAYSON | E37: DOMINGO
A38: ACOSTA, JEMY ARMYN BLANZA | B38: 002500 | C38: ACOSTA | D38: JEMY ARMYN | E38: BLANZA
A39: ACOSTA, JERICO ALLAN CALUYA | B39: 000590 | C39: ACOSTA | D39: JERICO ALLAN | E39: CALUYA
A40: ACOSTA, JESSIE JAMES CALUYA | B40: 002129 | C40: ACOSTA | D40: JESSIE JAMES | E40: CALUYA
A41: ACOSTA, JONATHAN CALUYA | B41: 001808 | C41: ACOSTA | D41: JONATHAN | E41: CALUYA
A42: ACOSTA, MA. ANGELICA TORIBIO | B42: 002953 | C42: ACOSTA | D42: MA. ANGELICA | E42: TORIBIO
A43: ACUÑA, GRACHELE CHARM ASUNCION | B43: 002704 | C43: ACUÑA | D43: GRACHELE CHARM | E43: ASUNCION
A44: ADALLA, LYLA EDISSEY FLOJO | B44: 001079 | C44: ADALLA | D44: LYLA EDISSEY | E44: FLOJO
... A46: ADAME, NIÑA MARIE PANGANIBAN | B46: 002479 | C46: ADAME | D46: NIÑA MARIE | E46: PANGANIBAN
A47: ADOLFO, JOSHUA | B47: 002830 | C47: ADOLFO | D47: JOSHUA
A48: ADVINCULA, MARY ANTONETTE RAÑA | B48: 001532 | C48: ADVINCULA | D48: MARY ANTONETTE | E48: RAÑA
A49: AFROILAN, REGIENALD ACAIN | B49: 002160 | C49: AFROILAN | D49: REGIENALD | E49: ACAIN
A50: AGABIN, JANE CHRISTINE VERGARA | B50: 001509 | C50: AGABIN | D50: JANE CHRISTINE | E50: VERGARA
A51: AGACIA, JEANIN REMEBEL PEDROLA | B51: GIP-061 | C51: AGACIA | D51: JEANIN REMEBEL | E51: PEDROLA
A52: AGACIA, RACHELLE MAE COLOMA | B52: 001272 | C52: AGACIA | D52: RACHELLE MAE | E52: COLOMA
A53: AGANUS, KRISTINE JOY MATABANG | B53: 001185 | C53: AGANUS | D53: KRISTINE JOY | E53: MATABANG
A54: AGARPAO, ESPERANZA GUILLERMO | B54: 000104 | C54: AGARPAO | D54: ESPERANZA | E54: GUILLERMO
A55: AGARPAO, SHELLA MAY BALBAG | B55: 001588 | C55: AGARPAO | D55: SHELLA MAY | E55: BALBAG
A56: AGAS, MHEL ANTHONY | B56: 002971 | C56: AGAS | D56: MHEL ANTHONY
A57: AGBANNAOAG, JULIMAR MORALES | B57: 001628 | C57: AGBANNAOAG | D57: JULIMAR | E57: MORALES
A58: AGBAYANI, ELYKA LAURECE DOROYAN | B58: 002952 | C58: AGBAYANI | D58: ELYKA LAURECE | E58: DOROYAN
A59: AGBAYANI, MARK LAURENCE DOROYAN | B59: 002515 | C59: AGBAYANI | D59: MARK LAURENCE | E59: DOROYAN
...

Sheet Employee Dropdown Lists
A1: Row 5 | B1: Row 6 | C1: Row 7 | D1: Row 8 | E1: Row 9 | F1: Row 10 | G1: Row 11 | H1: Row 12 | I1: Row 13 | J1: Row 14 | K1: Row 15 | L1: Row 16 | M1: Row 17 | N1: Row 18 | O1: Row 19 | P1: Row 20 | Q1: Row 21 | R1: Row 22 | S1: Row 23 | T1: Row 24 | U1: Row 25 | V1: Row 26 | W1: Row 27 | X1: Row 28 | Y1: Row 29 | Z1: Row 30 | AA1: Row 31 | AB1: Row 32 | AC1: Row 33 | AD1: Row 34 | AE1: Row 35 | AF1: Row 36 | AG1: Row 37 | AH1: Row 38 | AI1: Row 39 | AJ1: Row 40 | AK1: Row 41 | AL1: Row 42 | AM1: Row 43 | AN1: Row 44 | AO1: Row 45 | AP1: Row 46 | AQ1: Row 47 | AR1: Row 48 | AS1: Row 49 | AT1: Row 50 | AU1: Row 51 | AV1: Row 52 | AW1: Row 53 | AX1: Row 54 | AY1: Row 55 | AZ1: Row 56 | BA1: Row 57 | BB1: Row 58 | BC1: Row 59 | BD1: Row 60 | BE1: Row 61 | BF1: Row 62 | BG1: Row 63 | BH1: Row 64 | BI1: Row 65 | BJ1: Row 66 | BK1: Row 67 | BL1: Row 68 | BM1: Row 69 | BN1: Row 70 | BO1: Row 71 | BP1: Row 72 | BQ1: Row 73 | BR1: Row 74 | BS1: Row 75 | BT1: Row 76 | BU1: Row 77 | BV1: Row 78 | BW1: Row 79 | BX1: Row 80 | BY1: Row 81 | BZ1: Row 82 | CA1: Row 83 | CB1: Row 84 | CC1: Row 85 | CD1: Row 86 | CE1: Row 87 | CF1: Row 88 | CG1: Row 89 | CH1: Row 90 | CI1: Row 91 | CJ1: Row 92 | CK1: Row 93 | CL1: Row 94 | CM1: Row 95 | CN1: Row 96 | CO1: Row 97 | CP1: Row 98 | CQ1: Row 99 | CR1: Row 100 | CS1: Row 101 | CT1: Row 102 | CU1: Row 103 | CV1: Row 104 | CW1: Row 105 | CX1: Row 106 | CY1: Row 107 | CZ1: Row 108 | DA1: Row 109 | DB1: Row 110 | DC1: Row 111 | DD1: Row 112 | DE1: Row 113 | DF1: Row 114 | DG1: Row 115 | DH1: Row 116 | DI1: Row 117 | DJ1: Row 118 | DK1: Row 119 | DL1: Row 120 | DM1: Row 121 | DN1: Row 122 | DO1: Row 123 | DP1: Row 124 | DQ1: Row 125 | DR1: Row 126 | DS1: Row 127 | DT1: Row 128 | DU1: Row 129 | DV1: Row 130 | DW1: Row 131 | DX1: Row 132 | DY1: Row 133 | DZ1: Row 134 | EA1: Row 135 | EB1: Row 136 | EC1: Row 137 | ED1: Row 138 | EE1: Row 139 | EF1: Row 140 | EG1: Row 141 | EH1: Row 142 | EI1: Row 143 | EJ1: Row 144 | EK1: Row 145 | EL1: Row 146 | EM1: Row 147 | EN1: Row 148 | EO1: Row 149 | EP1: Row 150 | EQ1: Row 151 | ER1: Row 152 | ES1: Row 153 | ET1: Row 154 | EU1: Row 155 | EV1: Row 156 | EW1: Row 157 | EX1: Row 158 | EY1: Row 159 | EZ1: Row 160 | FA1: Row 161 | FB1: Row 162 | FC1: Row 163 | FD1: Row 164 | FE1: Row 165 | FF1: Row 166 | FG1: Row 167 | FH1: Row 168 | FI1: Row 169 | FJ1: Row 170 | FK1: Row 171 | FL1: Row 172 | FM1: Row 173 | FN1: Row 174 | FO1: Row 175 | FP1: Row 176 | FQ1: Row 177 | FR1: Row 178 | FS1: Row 179 | FT1: Row 180 | FU1: Row 181 | FV1: Row 182 | FW1: Row 183 | FX1: Row 184 | FY1: Row 185 | FZ1: Row 186 | GA1: Row 187 | GB1: Row 188 | GC1: Row 189 | GD1: Row 190 | GE1: Row 191 | GF1: Row 192 | GG1: Row 193 | GH1: Row 194 | GI1: Row 195 | GJ1: Row 196 | GK1: Row 197 | GL1: Row 198 | GM1: Row 199 | GN1: Row 200 | GO1: Row 201 | GP1: Row 202 | GQ1: Row 203 | GR1: Row 204 | GS1: Row 205 | GT1: Row 206 | GU1: Row 207 | GV1: Row 208 | GW1: Row 209 | GX1: Row 210 | GY1: Row 211 | GZ1: Row 212 | HA1: Row 213 | HB1: Row 214 | HC1: Row 215 | HD1: Row 216 | HE1: Row 217 | HF1: Row 218 | HG1: Row 219 | HH1: Row 220 | HI1: Row 221 | HJ1: Row 222 | HK1: Row 223 | HL1: Row 224 | HM1: Row 225 | HN1: Row 226 | HO1: Row 227 | HP1: Row 228 | HQ1: Row 229 | HR1: Row 230 | HS1: Row 231 | HT1: Row 232 | HU1: Row 233 | HV1: Row 234 | HW1: Row 235 | HX1: Row 236 | HY1: Row 237 | HZ1: Row 238 | IA1: Row 239 | IB1: Row 240 | IC1: Row 241 | ID1: Row 242 | IE1: Row 243 | IF1: Row 244 | IG1: Row 245 | IH1: Row 246 | II1: Row 247 | IJ1: Row 248 | IK1: Row 249 | IL1: Row 250 | IM1: Row 251 | IN1: Row 252 | IO1: Row 253 | IP1: Row 254 | IQ1: Row 255 | IR1: Row 256 | IS1: Row 257 | IT1: Row 258 | IU1: Row 259 | IV1: Row 260 | IW1: Row 261 | IX1: Row 262 | IY1: Row 263 | IZ1: Row 264 | JA1: Row 265 | JB1: Row 266 | JC1: Row 267 | JD1: Row 268 | JE1: Row 269 | JF1: Row 270 | JG1: Row 271 | JH1: Row 272 | JI1: Row 273 | JJ1: Row 274 | JK1: Row 275 | JL1: Row 276 | JM1: Row 277 | JN1: Row 278 | JO1: Row 279 | JP1: Row 280 | JQ1: Row 281 | JR1: Row 282 | JS1: Row 283 | JT1: Row 284 | JU1: Row 285 | JV1: Row 286 | JW1: Row 287 | JX1: Row 288 | JY1: Row 289 | JZ1: Row 290 | KA1: Row 291 | KB1: Row 292 | KC1: Row 293 | KD1: Row 294 | KE1: Row 295 | KF1: Row 296 | KG1: Row 297 | KH1: Row 298 | KI1: Row 299 | KJ1: Row 300 | KK1: Row 301 | KL1: Row 302 | KM1: Row 303 | KN1: Row 304 | KO1: Row 305 | KP1: Row 306 | KQ1: Row 307 | KR1: Row 308 | KS1: Row 309 | KT1: Row 310 | KU1: Row 311 | KV1: Row 312 | KW1: Row 313 | KX1: Row 314 | KY1: Row 315 | KZ1: Row 316 | LA1: Row 317 | LB1: Row 318 | LC1: Row 319 | LD1: Row 320 | LE1: Row 321 | LF1: Row 322 | LG1: Row 323 | LH1: Row 324 | LI1: Row 325 | LJ1: Row 326 | LK1: Row 327 | LL1: Row 328 | LM1: Row 329 | LN1: Row 330 | LO1: Row 331 | LP1: Row 332 | LQ1: Row 333 | LR1: Row 334 | LS1: Row 335 | LT1: Row 336 | LU1: Row 337 | LV1: Row 338 | LW1: Row 339 | LX1: Row 340 | LY1: Row 341 | LZ1: Row 342 | MA1: Row 343 | MB1: Row 344 | MC1: Row 345 | MD1: Row 346 | ME1: Row 347 | MF1: Row 348 | MG1: Row 349 | MH1: Row 350 | MI1: Row 351 | MJ1: Row 352 | MK1: Row 353 | ML1: Row 354 | MM1: Row 355 | MN1: Row 356 | MO1: Row 357 | MP1: Row 358 | MQ1: Row 359 | MR1: Row 360 | MS1: Row 361 | MT1: Row 362 | MU1: Row 363 | MV1: Row 364 | MW1: Row 365 | MX1: Row 366 | MY1: Row 367 | MZ1: Row 368 | NA1: Row 369 | NB1: Row 370 | NC1: Row 371 | ND1: Row 372 | NE1: Row 373 | NF1: Row 374 | NG1: Row 375 | NH1: Row 376 | NI1: Row 377 | NJ1: Row 378 | NK1: Row 379 | NL1: Row 380 | NM1: Row 381 | NN1: Row 382 | NO1: Row 383 | NP1: Row 384 | NQ1: Row 385 | NR1: Row 386 | NS1: Row 387 | NT1: Row 388 | NU1: Row 389 | NV1: Row 390 | NW1: Row 391 | NX1: Row 392 | NY1: Row 393 | NZ1: Row 394 | OA1: Row 395 | OB1: Row 396 | OC1: Row 397 | OD1: Row 398 | OE1: Row 399 | OF1: Row 400 | OG1: Row 401 | OH1: Row 402 | OI1: Row 403 | OJ1: Row 404 | OK1: Row 405 | OL1: Row 406 | OM1: Row 407 | ON1: Row 408 | OO1: Row 409 | OP1: Row 410 | OQ1: Row 411 | OR1: Row 412 | OS1: Row 413 | OT1: Row 414 | OU1: Row 415 | OV1: Row 416 | OW1: Row 417 | OX1: Row 418 | OY1: Row 419 | OZ1: Row 420 | PA1: Row 421 | PB1: Row 422 | PC1: Row 423 | PD1: Row 424 | PE1: Row 425 | PF1: Row 426 | PG1: Row 427 | PH1: Row 428 | PI1: Row 429 | PJ1: Row 430 | PK1: Row 431 | PL1: Row 432 | PM1: Row 433 | PN1: Row 434 | PO1: Row 435 | PP1: Row 436 | PQ1: Row 437 | PR1: Row 438 | PS1: Row 439 | PT1: Row 440 | PU1: Row 441 | PV1: Row 442 | PW1: Row 443 | PX1: Row 444 | PY1: Row 445 | PZ1: Row 446 | QA1: Row 447 | QB1: Row 448 | QC1: Row 449 | QD1: Row 450 | QE1: Row 451 | QF1: Row 452 | QG1: Row 453 | QH1: Row 454 | QI1: Row 455 | QJ1: Row 456 | QK1: Row 457 | QL1: Row 458 | QM1: Row 459 | QN1: Row 460 | QO1: Row 461 | QP1: Row 462 | QQ1: Row 463 | QR1: Row 464 | QS1: Row 465 | QT1: Row 466 | QU1: Row 467 | QV1: Row 468 | QW1: Row 469 | QX1: Row 470 | QY1: Row 471 | QZ1: Row 472 | RA1: Row 473 | RB1: Row 474 | RC1: Row 475 | RD1: Row 476 | RE1: Row 477 | RF1: Row 478 | RG1: Row 479 | RH1: Row 480 | RI1: Row 481 | RJ1: Row 482 | RK1: Row 483 | RL1: Row 484 | RM1: Row 485 | RN1: Row 486 | RO1: Row 487 | RP1: Row 488 | RQ1: Row 489 | RR1: Row 490 | RS1: Row 491 | RT1: Row 492 | RU1: Row 493 | RV1: Row 494 | RW1: Row 495 | RX1: Row 496 | RY1: Row 497 | RZ1: Row 498 | SA1: Row 499 | SB1: Row 500 | SC1: Row 501 | SD1: Row 502 | SE1: Row 503 | SF1: Row 504
